Workbook
Name ava: 'Average Total Assets'!$F:$F
Name kode: 'Average Total Assets'!$B:$B
Name th: 'Average Total Assets'!$C:$C

Sheet Average Total Assets
A1: No | B1: Kode Emiten | C1: Tahun | D1: Beginning Total Asset | E1: End Total Assets | F1: Average Total Assets
A2: 1 | B2: ASTJ | C2: 2017 | D2: 427094000000 | E2: 446108163202 | F2: =(D2+E2)/2 -> 436601081601
A3: 2 | B3: ASTJ | C3: 2018 | D3: 446108163202 | E3: 478439333039 | F3: =(D3+E3)/2 -> 4.6227375e+11
A4: 3 | B4: ASTJ | C4: 2019 | D4: 478439333039 | E4: 447670324778 | F4: =(D4+E4)/2 -> 4.6305483e+11
A5: 4 | B5: ASTJ | C5: 2020 | D5: 447670324778 | E5: 365763908254 | F5: =(D5+E5)/2 -> 406717116516
A6: 5 | B6: ASTJ | C6: 2021 | D6: 365763908254 | E6: 527852244647 | F6: =(D6+E6)/2 -> 4.4680808e+11
A7: 6 | B7: ASMI | C7: 2017 | D7: 617651155745 | E7: 858490283480 | F7: =(D7+E7)/2 -> 7.3807072e+11
A8: 7 | B8: ASMI | C8: 2018 | D8: 858490283480 | E8: 969866560976 | F8: =(D8+E8)/2 -> 914178422228
A9: 8 | B9: ASMI | C9: 2019 | D9: 969866560976 | E9: 975687462693 | F9: =(D9+E9)/2 -> 9.7277701e+11
A10: 9 | B10: ASMI | C10: 2020 | D10: 975687462693 | E10: 990991744064 | F10: =(D10+E10)/2 -> 9.833396e+11
A11: 10 | B11: ASMI | C11: 2021 | D11: 990991744064 | E11: 981089572950 | F11: =(D11+E11)/2 -> 986040658507
A12: 11 | B12: BBNI | C12: 2017 | D12: 603031880000000 | E12: 709330084000000 | F12: =(D12+E12)/2 -> 656180982000000
A13: 12 | B13: BBNI | C13: 2018 | D13: 709330084000000 | E13: 808572011000000 | F13: =(D13+E13)/2 -> 758951047500000
... A102: 101 | B102: ASDM | C102: 2017 | D102: 1063856088000 | E102: 1076575416000 | F102: =(D102+E102)/2 -> 1070215752000
A103: 102 | C103: 2018 | D103: =E102 -> 1076575416000 | E103: 1061398832000 | F103: =(D103+E103)/2 -> 1068987124000
A104: 103 | C104: 2019 | D104: =E103 -> 1061398832000 | E104: 1158038755000 | F104: =(D104+E104)/2 -> 1109718793500
A105: 104 | C105: 2020 | D105: =E104 -> 1158038755000 | E105: 859876511000 | F105: =(D105+E105)/2 -> 1008957633000
A106: 105 | C106: 2021 | D106: =E105 -> 859876511000 | E106: 822740369000 | F106: =(D106+E106)/2 -> 841308440000
A107: 106 | B107: BBKP | C107: 2017 | D107: 105406002000000 | E107: 106442999000000 | F107: =(D107+E107)/2 -> 105924500500000
A108: 107 | C108: 2018 | D108: =E107 -> 106442999000000 | E108: 95643923000000 | F108: =(D108+E108)/2 -> 101043461000000
A109: 108 | C109: 2019 | D109: =E108 -> 95643923000000 | E109: 100264248000000 | F109: =(D109+E109)/2 -> 97954085500000
A110: 109 | C110: 2020 | D110: =E109 -> 100264248000000 | E110: 79938578000000 | F110: =(D110+E110)/2 -> 90101413000000
A111: 110 | C111: 2021 | D111: =E110 -> 79938578000000 | E111: 89215674000000 | F111: =(D111+E111)/2 -> 84577126000000
A112: 111 | B112: BBMD | C112: 2017 | D112: 10588224193569 | E112: 11817844456356 | F112: =(D112+E112)/2 -> 1.1203034e+13
A113: 112 | C113: 2018 | D113: =E112 -> 11817844456356 | E113: 12093079368934 | F113: =(D113+E113)/2 -> 11955461912645
A114: 113 | C114: 2019 | D114: =E113 -> 12093079368934 | E114: 12900218775263 | F114: =(D114+E114)/2 -> 1.2496649e+13
A115: 114 | C115: 2020 | D115: =E114 -> 12900218775263 | E115: 14159755232533 | F115: =(D115+E115)/2 -> 13529987003898
A116: 115 | C116: 2021 | D116: =E115 -> 14159755232533 | E116: 15983152301240 | F116: =(D116+E116)/2 -> 1.5071454e+13
A117: 116 | B117: BBRI | C117: 2017 | D117: 878426312000000 | E117: 1.1274475e+15 | F117: =(D117+E117)/2 -> 1.0029369e+15
A118: 117 | C118: 2018 | D118: =E117 -> 1.1274475e+15 | E118: 1.2968983e+15 | F118: =(D118+E118)/2 -> 1.2121729e+15
A119: 118 | C119: 2019 | D119: =E118 -> 1.2968983e+15 | E119: 1.4167588e+15 | F119: =(D119+E119)/2 -> 1.3568286e+15
A120: 119 | C120: 2020 | D120: =E119 -> 1.4167588e+15 | E120: 1.6100653e+15 | F120: =(D120+E120)/2 -> 1.5134121e+15
A121: 120 | C121: 2021 | D121: =E120 -> 1.6100653e+15 | E121: 1.6780977e+15 | F121: =(D121+E121)/2 -> 1.6440815e+15
A122: 121 | B122: BBYB | C122: 2017 | D122: 4846528413826 | E122: 5004795018159 | F122: =(D122+E122)/2 -> 4.9256617e+12
A123: 122 | C123: 2018 | D123: =E122 -> 5004795018159 | E123: 4533729146622 | F123: =(D123+E123)/2 -> 4.7692621e+12
A124: 123 | C124: 2019 | D124: =E123 -> 4533729146622 | E124: 5123734649117 | F124: =(D124+E124)/2 -> 4.8287319e+12
A125: 124 | C125: 2020 | D125: =E124 -> 5123734649117 | E125: 5421324398438 | F125: =(D125+E125)/2 -> 5.2725295e+12
A126: 125 | C126: 2021 | D126: =E125 -> 5421324398438 | E126: 11337808684383 | F126: =(D126+E126)/2 -> 8.3795665e+12
A127: 126 | B127: BINA | C127: 2017 | D127: 2359089000000 | E127: 3123345000000 | F127: =(D127+E127)/2 -> 2741217000000
A128: 127 | C128: 2018 | D128: =E127 -> 3123345000000 | E128: 3854174000000 | F128: =(D128+E128)/2 -> 3488759500000
...

Sheet ch receivable
A1: No | B1: Kode Emiten | C1: Tahun | D1: Receivable | E1: ∆Receivable | F1: Average Total Assets | G1: CH Rec
A2: 1 | B2: ASTJ | C2: 2017 | D2: =76508107097+14346522792+751105407+13696137698 -> 105301872994 | E2: 0 | F2: 0 | G2: =E2/F2 -> #DIV/0!
A3: 2 | B3: ASTJ | C3: 2018 | D3: =83935111290+13126436678+903019323+11339863183 -> 109304430474 | E3: =D3-D2 -> 4002557480 | F3: 4.6227375e+11 | G3: =E3/F3 -> 0.008658414
A4: 3 | B4: ASTJ | C4: 2019 | D4: =6105094632+62107180919+24373745095+861805626+5970752073+1924322503 -> 101342900848 | E4: =D4-D3 -> -7961529626 | F4: 4.6305483e+11 | G4: =E4/F4 -> -0.017193492
A5: 4 | B5: ASTJ | C5: 2020 | D5: =10909190618+42582398713+43449304553+5670752073+3984951463 -> 106596597420 | E5: =D5-D4 -> 5253696572 | F5: 406717116516 | G5: =E5/F5 -> 0.012917324
A6: 5 | B6: ASTJ | C6: 2021 | D6: =16585607499+52452053623+51368504280+732763300+4928158953+6746881380 -> 132813969035 | E6: =D6-D5 -> 26217371615 | F6: 4.4680808e+11 | G6: =E6/F6 -> 0.058677032
A7: 6 | B7: ASMI | C7: 2017 | D7: =21755720+113476086563+13986354548+12174889005 -> 139659085836 | G7: =E7/F7 -> #DIV/0!
A8: 7 | B8: ASMI | C8: 2018 | D8: =5695950+141393596454+26280788985+12864574994 -> 180544656383 | E8: =D8-D7 -> 40885570547 | F8: 914178422228 | G8: =E8/F8 -> 0.044723841
A9: 8 | B9: ASMI | C9: 2019 | D9: =11736375+107397784947+60102707851+8281893868 -> 175794123041 | E9: =D9-D8 -> -4750533342 | F9: 9.7277701e+11 | G9: =E9/F9 -> -0.0048834762
A10: 9 | B10: ASMI | C10: 2020 | D10: =10035000+106128409949+148962330950+7680263492 -> 262781039391 | E10: =D10-D9 -> 86986916350 | F10: 9.833396e+11 | G10: =E10/F10 -> 0.088460707
A11: 10 | B11: ASMI | C11: 2021 | D11: =65234343420+132635142107+5243671084 -> 203113156611 | E11: =D11-D10 -> -59667882780 | F11: 986040658507 | G11: =E11/F11 -> -0.060512599
A12: 11 | B12: BBNI | C12: 2017 | D12: =3254353000000+2813466000000+2766507000000+71388000000+18106412000000+216884000000+426789981000000 -> 454018991000000 | G12: =E12/F12 -> #DIV/0!
A13: 12 | B13: BBNI | C13: 2018 | D13: =4253128000000+3429531000000+17000000+20295277000000+605248000000+497886888000000 -> 526470089000000 | E13: =D13-D12 -> 72451098000000 | F13: 758951047500000 | G13: =E13/F13 -> 0.095462149
A14: 13 | B14: BBNI | C14: 2019 | D14: =3220178000000+3785287000000+2571286000000+18558276000000+312266000000+539862076000000 -> 568309369000000 | E14: =D14-D13 -> 41839280000000 | F14: 827088609500000 | G14: =E14/F14 -> 0.050586212
A15: 14 | B15: BBNI | C15: 2020 | D15: =3908683000000+3874790000000+2382329000000+20575666000000+140614000000+541978801000000 -> 572860883000000 | E15: =D15-D14 -> 4551514000000 | F15: 868471316500000 | G15: =E15/F15 -> 0.005240834
A16: 15 | B16: BBNI | C16: 2021 | D16: =3333395000000+3057796000000+2051031000000+20542767000000+494183000000+532141344000000 -> 561620516000000 | E16: =D16-D15 -> -11240367000000 | F16: 928087558500000 | G16: =E16/F16 -> -0.012111322
A17: 16 | B17: BBTN | C17: 2017 | D17: =196634594000000+8081000000 -> 196642675000000 | G17: =E17/F17 -> #DIV/0!
A18: 17 | B18: BBTN | C18: 2018 | D18: =234459542000000+528148000000 -> 234987690000000 | E18: =D18-D17 -> 38345015000000 | F18: 283900730500000 | G18: =E18/F18 -> 0.13506487
A19: 18 | B19: BBTN | C19: 2019 | D19: =249708993000000+487052000000 -> 250196045000000 | E19: =D19-D18 -> 15208355000000 | F19: 309106511000000 | G19: =E19/F19 -> 0.049201018
A20: 19 | B20: BBTN | C20: 2020 | D20: =247053220000000+194678000000+70366000000 -> 247318264000000 | E20: =D20-D19 -> -2877781000000 | F20: 336492617000000 | G20: =E20/F20 -> -0.0085522857
A21: 20 | B21: BBTN | C21: 2021 | D21: =260399531000000+31017000000+453517000000 -> 260884065000000 | E21: =D21-D20 -> 13565801000000 | F21: 366538358500000 | G21: =E21/F21 -> 0.03701059
A22: 21 | B22: BCAP | C22: 2017 | D22: =237072000000+811042000000+184885000000+2640852000000-22184000000+555000000+305296000000-2714000000+169120000000-247000000 -> 4323677000000 | G22: =E22/F22 -> #DIV/0!
A23: 22 | B23: BCAP | C23: 2018 | D23: =119242000000+383410000000+369483000000+1917798000000-21885000000+519000000+135696000000-120000000+85125000000-2136000000 -> 2987132000000 | E23: =D23-D22 -> -1336545000000 | F23: 19322993500000 | G23: =E23/F23 -> -0.069168631
A24: 23 | B24: BCAP | C24: 2019 | D24: =169859000000+411428000000+191148000000+1763073000000-22167000000+8965000000+28439000000-1092000000+50897000000-2792000000 -> 2597758000000 | E24: =D24-D23 -> -389374000000 | F24: 18573864500000 | G24: =E24/F24 -> -0.020963543
A25: 24 | B25: BCAP | C25: 2020 | D25: =340136000000+680541000000+180993000000+1390494000000-15447000000+4768000000+89000000-12000000+13316000000-324000000 -> 2594554000000 | E25: =D25-D24 -> -3204000000 | F25: 18743275500000 | G25: =E25/F25 -> -0.00017094131
A26: 25 | B26: BCAP | C26: 2021 | D26: =291740000000+474897000000+208289000000+1317356000000-13338000000+1654000000+3674000000+21610000000-7000000 -> 2305875000000 | E26: =D26-D25 -> -288679000000 | F26: 20377757000000 | G26: =E26/F26 -> -0.014166378
A27: 26 | B27: BDMN | C27: 2017 | D27: =413000000+103493000000+26080060000000+369488000000+1465000000+251502000000+2468000000+1483472000000+71783000000+93973723000000 -> 122337867000000 | G27: =E27/F27 -> #DIV/0!
A28: 27 | B28: BDMN | C28: 2018 | D28: =54553000000+394538000000+28262631000000+240623000000+1679176000000+71783000000+93973723000000 -> 124677027000000 | E28: =D28-D27 -> 2339160000000 | F28: 182509640500000 | G28: =E28/F28 -> 0.012816638
A29: 28 | B29: BDMN | C29: 2019 | D29: =159123000000+29624404000000+290517000000+862696000000+69720000000+106795782000000 -> 137802242000000 | E29: =D29-D28 -> 13125215000000 | F29: 190148079500000 | G29: =E29/F29 -> 0.069026282
A30: 29 | B30: BDMN | C30: 2020 | D30: =362482000000+22605362000000+246644000000+1592400000000+41365000000+103895653000000 -> 128743906000000 | E30: =D30-D29 -> -9058336000000 | F30: 197212019000000 | G30: =E30/F30 -> -0.045931967
A31: 30 | B31: BDMN | C31: 2021 | D31: =187297000000+19958199000000+280613000000+2058574000000+30506000000+99935455000000 -> 122450644000000 | E31: =D31-D30 -> -6293262000000 | F31: 196564883000000 | G31: =E31/F31 -> -0.032016207
A32: 31 | B32: BFIN | C32: 2017 | D32: =9435315000000+5739410000000+414127000000 -> 15588852000000 | G32: =E32/F32 -> #DIV/0!
A33: 32 | B33: BFIN | C33: 2018 | D33: =11357670000000+5922788000000+105000000+198271000000 -> 17478834000000 | E33: =D33-D32 -> 1889982000000 | F33: 17800289000000 | G33: =E33/F33 -> 0.10617704
A34: 33 | B34: BFIN | C34: 2019 | D34: =17395920000000+2105000000+153494000000 -> 17551519000000 | E34: =D34-D33 -> 72685000000 | F34: 19103469000000 | G34: =E34/F34 -> 0.0038048063
A35: 34 | B35: BFIN | C35: 2020 | D35: =12678444000000+586000000+154904000000 -> 12833934000000 | E35: =D35-D34 -> -4717585000000 | F35: 17145082000000 | G35: =E35/F35 -> -0.27515675
A36: 35 | B36: BFIN | C36: 2021 | D36: =13676190000000+941000000+87089000000 -> 13764220000000 | E36: =D36-D35 -> 930286000000 | F36: 15418135000000 | G36: =E36/F36 -> 0.060337129
A37: 36 | B37: BNGA | C37: 2017 | D37: =280293000000+181405722000000+3710084000000+10936000000+4184965000000 -> 189592000000000 | G37: =E37/F37 -> #DIV/0!
A38: 37 | B38: BNGA | C38: 2018 | D38: =1084759000000+180311277000000+2052802000000+1180000000+4462483000000 -> 187912501000000 | E38: =D38-D37 -> -1679499000000 | F38: 266543476500000 | G38: =E38/F38 -> -0.0063010321
A39: 38 | B39: BNGA | C39: 2019 | D39: =725478000000+184998140000000+3179370000000+3767071000000 -> 192670059000000 | E39: =D39-D38 -> 4757558000000 | F39: 270624362500000 | G39: =E39/F39 -> 0.017579932
A40: 39 | B40: BNGA | C40: 2020 | D40: =1359286000000+159851784000000+2977849000000+2022665000000 -> 166211584000000 | E40: =D40-D39 -> -26458475000000 | F40: 277705416000000 | G40: =E40/F40 -> -0.095275329
...

Sheet ch in cash sales
C1: No | D1: Kode Emiten | E1: Tahun | F1: Sales/Pendapatan | G1: ∆Sales | H1: Receivable(t) | I1: ∆Receivable | J1: Ch in Sales
C2: 1 | D2: ASTJ | E2: 2017 | F2: 174285978503 | G2: 0 | H2: =76508107097+14346522792+751105407+13696137698 -> 105301872994 | I2: 0 | J2: =(G2/F2)-(I2/H2) -> 0
C3: 2 | D3: ASTJ | E3: 2018 | F3: =163165384062 -> 163165384062 | G3: =F3-F2 -> -11120594441 | H3: =83935111290+13126436678+903019323+11339863183 -> 109304430474 | I3: =H3-H2 -> 4002557480 | J3: =(G3/F3)-(I3/H3) -> -0.10477379
C4: 3 | D4: ASTJ | E4: 2019 | F4: 152809529035 | G4: =F4-F3 -> -10355855027 | H4: =6105094632+62107180919+24373745095+861805626+5970752073+1924322503 -> 101342900848 | I4: =H4-H3 -> -7961529626 | J4: =(G4/F4)-(I4/H4) -> 0.010790615
C5: 4 | D5: ASTJ | E5: 2020 | F5: 107091468350 | G5: =F5-F4 -> -45718060685 | H5: =10909190618+42582398713+43449304553+5670752073+3984951463 -> 106596597420 | I5: =H5-H4 -> 5253696572 | J5: =(G5/F5)-(I5/H5) -> -0.47619244
C6: 5 | D6: ASTJ | E6: 2021 | F6: 115490756693 | G6: =F6-F5 -> 8399288343 | H6: =16585607499+52452053623+51368504280+732763300+4928158953+6746881380 -> 132813969035 | I6: =H6-H5 -> 26217371615 | J6: =(G6/F6)-(I6/H6) -> -0.12467227
C7: 6 | D7: ASMI | E7: 2017 | F7: 58790955548 | H7: =21755720+113476086563+13986354548+12174889005 -> 139659085836 | J7: =(G7/F7)-(I7/H7) -> 0
C8: 7 | D8: ASMI | E8: 2018 | F8: 67042246193 | G8: =F8-F7 -> 8251290645 | H8: =5695950+141393596454+26280788985+12864574994 -> 180544656383 | I8: =H8-H7 -> 40885570547 | J8: =(G8/F8)-(I8/H8) -> -0.10338084
C9: 8 | D9: ASMI | E9: 2019 | F9: 73219691954 | G9: =F9-F8 -> 6177445761 | H9: =11736375+107397784947+60102707851+8281893868 -> 175794123041 | I9: =H9-H8 -> -4750533342 | J9: =(G9/F9)-(I9/H9) -> 0.11139192
C10: 9 | D10: ASMI | E10: 2020 | F10: 63829169140 | G10: =F10-F9 -> -9390522814 | H10: =10035000+106128409949+148962330950+7680263492 -> 262781039391 | I10: =H10-H9 -> 86986916350 | J10: =(G10/F10)-(I10/H10) -> -0.47814394
C11: 10 | D11: ASMI | E11: 2021 | F11: 27094983645 | G11: =-(F11-F10) -> 36734185495 | H11: =65234343420+132635142107+5243671084 -> 203113156611 | I11: =H11-H10 -> -59667882780 | J11: =(G11/F11)-(I11/H11) -> 1.6495227
C12: 11 | D12: BBNI | E12: 2017 | F12: =48177849000000+31937763000000+1767568000000+11040059000000 -> 92923239000000 | H12: =3254353000000+2813466000000+2766507000000+71388000000+18106412000000+216884000000+426789981000000 -> 454018991000000 | J12: =(G12/F12)-(I12/H12) -> 0
C13: 12 | D13: BBNI | E13: 2018 | F13: =54138613000000+35446315000000+1711857000000+11612599000000 -> 102909384000000 | G13: =F13-F12 -> 9986145000000 | H13: =4253128000000+3429531000000+17000000+20295277000000+605248000000+497886888000000 -> 526470089000000 | I13: =H13-H12 -> 72451098000000 | J13: =(G13/F13)-(I13/H13) -> -0.040578506
C14: 13 | D14: BBNI | E14: 2019 | F14: =58532373000000+36602374000000+1696928000000+13712398000000 -> 110544073000000 | G14: =F14-F13 -> 7634689000000 | H14: =3220178000000+3785287000000+2571286000000+18558276000000+312266000000+539862076000000 -> 568309369000000 | I14: =H14-H13 -> 41839280000000 | J14: =(G14/F14)-(I14/H14) -> -0.0045559441
C15: 14 | D15: BBNI | E15: 2020 | F15: =56172871000000+37151966000000+1471088000000+13412581000000 -> 108208506000000 | G15: =F15-F14 -> -2335567000000 | H15: =3908683000000+3874790000000+2382329000000+20575666000000+140614000000+541978801000000 -> 572860883000000 | I15: =H15-H14 -> 4551514000000 | J15: =(G15/F15)-(I15/H15) -> -0.029529185
C16: 15 | D16: BBNI | E16: 2021 | F16: =50025887000000+38246731000000+1398957000000+16219699000000 -> 105891274000000 | G16: =F16-F15 -> -2317232000000 | H16: =3333395000000+3057796000000+2051031000000+20542767000000+494183000000+532141344000000 -> 561620516000000 | I16: =H16-H15 -> -11240367000000 | J16: =(G16/F16)-(I16/H16) -> -0.0018689578
C17: 16 | D17: BBTN | E17: 2017 | F17: =22851758000000+1605931000000 -> 24457689000000 | H17: =196634594000000+8081000000 -> 196642675000000 | J17: =(G17/F17)-(I17/H17) -> 0
C18: 17 | D18: BBTN | E18: 2018 | F18: =22851758000000+2071594000000 -> 24923352000000 | G18: =F18-F17 -> 465663000000 | H18: =234459542000000+528148000000 -> 234987690000000 | I18: =H18-H17 -> 38345015000000 | J18: =(G18/F18)-(I18/H18) -> -0.14449502
C19: 18 | D19: BBTN | E19: 2019 | F19: =25719874000000+2109852000000 -> 27829726000000 | G19: =F19-F18 -> 2906374000000 | H19: =249708993000000+487052000000 -> 250196045000000 | I19: =H19-H18 -> 15208355000000 | J19: =(G19/F19)-(I19/H19) -> 0.043648405
C20: 19 | D20: BBTN | E20: 2020 | F20: =25105780000000+2514607000000 -> 27620387000000 | G20: =F20-F19 -> -209339000000 | H20: =247053220000000+194678000000+70366000000 -> 247318264000000 | I20: =H20-H19 -> -2877781000000 | J20: =(G20/F20)-(I20/H20) -> 0.0040567941
C21: 20 | D21: BBTN | E21: 2021 | F21: =25794958000000+2362567000000 -> 28157525000000 | G21: =F21-F20 -> 537138000000 | H21: =260399531000000+31017000000+453517000000 -> 260884065000000 | I21: =H21-H20 -> 13565801000000 | J21: =(G21/F21)-(I21/H21) -> -0.032923167
C22: 21 | D22: BCAP | E22: 2017 | F22: 2386245000000 | H22: =237072000000+811042000000+184885000000+2640852000000-22184000000+555000000+305296000000-2714000000+169120000000-247000000 -> 4323677000000 | J22: =(G22/F22)-(I22/H22) -> 0
C23: 22 | D23: BCAP | E23: 2018 | F23: 2661759000000 | G23: =F23-F22 -> 275514000000 | H23: =119242000000+383410000000+369483000000+1917798000000-21885000000+519000000+135696000000-120000000+85125000000-2136000000 -> 2987132000000 | I23: =H23-H22 -> -1336545000000 | J23: =(G23/F23)-(I23/H23) -> 0.55094244
C24: 23 | D24: BCAP | E24: 2019 | F24: 2737029000000 | G24: =F24-F23 -> 75270000000 | H24: =169859000000+411428000000+191148000000+1763073000000-22167000000+8965000000+28439000000-1092000000+50897000000-2792000000 -> 2597758000000 | I24: =H24-H23 -> -389374000000 | J24: =(G24/F24)-(I24/H24) -> 0.1773891
C25: 24 | D25: BCAP | E25: 2020 | F25: 2657232000000 | G25: =F25-F24 -> -79797000000 | H25: =340136000000+680541000000+180993000000+1390494000000-15447000000+4768000000+89000000-12000000+13316000000-324000000 -> 2594554000000 | I25: =H25-H24 -> -3204000000 | J25: =(G25/F25)-(I25/H25) -> -0.028795227
C26: 25 | D26: BCAP | E26: 2021 | F26: 2735142000000 | G26: =F26-F25 -> 77910000000 | H26: =291740000000+474897000000+208289000000+1317356000000-13338000000+1654000000+3674000000+21610000000-7000000 -> 2305875000000 | I26: =H26-H25 -> -288679000000 | J26: =(G26/F26)-(I26/H26) -> 0.15367763
C27: 26 | D27: BDMN | E27: 2017 | F27: =13979824000000+5110441000000 -> 19090265000000 | H27: =413000000+103493000000+26080060000000+369488000000+1465000000+251502000000+2468000000+1483472000000+71783000000+93973723000000 -> 122337867000000 | J27: =(G27/F27)-(I27/H27) -> 0
C28: 27 | D28: BDMN | E28: 2018 | F28: =14241084000000+5158037000000 -> 19399121000000 | G28: =F28-F27 -> 308856000000 | H28: =54553000000+394538000000+28262631000000+240623000000+1679176000000+71783000000+93973723000000 -> 124677027000000 | I28: =H28-H27 -> 2339160000000 | J28: =(G28/F28)-(I28/H28) -> -0.0028406226
C29: 28 | D29: BDMN | E29: 2019 | F29: =14579398000000+3273414000000 -> 17852812000000 | G29: =F29-F28 -> -1546309000000 | H29: =159123000000+29624404000000+290517000000+862696000000+69720000000+106795782000000 -> 137802242000000 | I29: =H29-H28 -> 13125215000000 | J29: =(G29/F29)-(I29/H29) -> -0.18186106
C30: 29 | D30: BDMN | E30: 2020 | F30: =13723663000000+2271140000000 -> 15994803000000 | G30: =F30-F29 -> -1858009000000 | H30: =362482000000+22605362000000+246644000000+1592400000000+41365000000+103895653000000 -> 128743906000000 | I30: =H30-H29 -> -9058336000000 | J30: =(G30/F30)-(I30/H30) -> -0.045803956
C31: 30 | D31: BDMN | E31: 2021 | F31: =13747222000000+2413819000000 -> 16161041000000 | G31: =F31-F30 -> 166238000000 | H31: =187297000000+19958199000000+280613000000+2058574000000+30506000000+99935455000000 -> 122450644000000 | I31: =H31-H30 -> -6293262000000 | J31: =(G31/F31)-(I31/H31) -> 0.061680617
C32: 31 | D32: BFIN | E32: 2017 | F32: 4042317000000 | H32: =9435315000000+5739410000000+414127000000 -> 15588852000000 | J32: =(G32/F32)-(I32/H32) -> 0
C33: 32 | D33: BFIN | E33: 2018 | F33: 5018243000000 | G33: =F33-F32 -> 975926000000 | H33: =11357670000000+5922788000000+105000000+198271000000 -> 17478834000000 | I33: =H33-H32 -> 1889982000000 | J33: =(G33/F33)-(I33/H33) -> 0.086345883
C34: 33 | D34: BFIN | E34: 2019 | F34: 5240729000000 | G34: =F34-F33 -> 222486000000 | H34: =17395920000000+2105000000+153494000000 -> 17551519000000 | I34: =H34-H33 -> 72685000000 | J34: =(G34/F34)-(I34/H34) -> 0.038312017
C35: 34 | D35: BFIN | E35: 2020 | F35: 4569778000000 | G35: =F35-F34 -> -670951000000 | H35: =12678444000000+586000000+154904000000 -> 12833934000000 | I35: =H35-H34 -> -4717585000000 | J35: =(G35/F35)-(I35/H35) -> 0.22076328
C36: 35 | D36: BFIN | E36: 2021 | F36: 4122555000000 | G36: =F36-F35 -> -447223000000 | H36: =13676190000000+941000000+87089000000 -> 13764220000000 | I36: =H36-H35 -> 930286000000 | J36: =(G36/F36)-(I36/H36) -> -0.17606926
C37: 36 | D37: BNGA | E37: 2017 | F37: =12403379000000+4106571000000 -> 16509950000000 | H37: =280293000000+181405722000000+3710084000000+10936000000+4184965000000 -> 189592000000000 | J37: =(G37/F37)-(I37/H37) -> 0
C38: 37 | D38: BNGA | E38: 2018 | F38: =12011731000000+4794343000000 -> 16806074000000 | G38: =F38-F37 -> 296124000000 | H38: =1084759000000+180311277000000+2052802000000+1180000000+4462483000000 -> 187912501000000 | I38: =H38-H37 -> -1679499000000 | J38: =(G38/F38)-(I38/H38) -> 0.026557723
C39: 38 | D39: BNGA | E39: 2019 | F39: =12568018000000+4933747000000 -> 17501765000000 | G39: =F39-F38 -> 695691000000 | H39: =725478000000+184998140000000+3179370000000+3767071000000 -> 192670059000000 | I39: =H39-H38 -> 4757558000000 | J39: =(G39/F39)-(I39/H39) -> 0.01505699
C40: 39 | D40: BNGA | E40: 2020 | F40: =12470518000000+2853855000000 -> 15324373000000 | G40: =F40-F39 -> -2177392000000 | H40: =1359286000000+159851784000000+2977849000000+2022665000000 -> 166211584000000 | I40: =H40-H39 -> -26458475000000 | J40: =(G40/F40)-(I40/H40) -> 0.017098648
...

Sheet Ch In earning
A1: No | B1: Kode Emiten | C1: Tahun | D1: Earning(t) | E1: Earning(t-1) | F1: Average Total Asset(t-1) | G1: Average Total Aset | H1: Ch in Earning
A2: 1 | B2: ASTJ | C2: 2017 | D2: 35616934582 | G2: 436601081601 | H2: =(D2/G2)-(E2/F2) -> #DIV/0!
A3: 2 | B3: ASTJ | C3: 2018 | D3: 10084095926 | E3: =D2 -> 35616934582 | F3: =G2 -> 436601081601 | G3: 4.6227375e+11 | H3: =(D3/G3)-(E3/F3) -> -0.05976363
A4: 3 | B4: ASTJ | C4: 2019 | D4: 2872717734 | E4: =D3 -> 10084095926 | F4: =G3 -> 4.6227375e+11 | G4: 4.6305483e+11 | H4: =(D4/G4)-(E4/F4) -> -0.015610283
A5: 4 | B5: ASTJ | C5: 2020 | D5: 171517965 | E5: =D4 -> 2872717734 | F5: =G4 -> 4.6305483e+11 | G5: 406717116516 | H5: =(D5/G5)-(E5/F5) -> -0.0057821261
A6: 5 | B6: ASTJ | C6: 2021 | D6: 718774542 | E6: =D5 -> 171517965 | F6: =G5 -> 406717116516 | G6: 4.4680808e+11 | H6: =(D6/G6)-(E6/F6) -> 0.0011869743
A7: 6 | B7: ASMI | C7: 2017 | D7: 61141112373 | G7: 7.3807072e+11 | H7: =(D7/G7)-(E7/F7) -> #DIV/0!
A8: 7 | B8: ASMI | C8: 2018 | D8: 64625986348 | E8: =D7 -> 61141112373 | F8: =G7 -> 7.3807072e+11 | G8: 914178422228 | H8: =(D8/G8)-(E8/F8) -> -0.012146129
A9: 8 | B9: ASMI | C9: 2019 | D9: 10700535196 | E9: =D8 -> 64625986348 | F9: =G8 -> 914178422228 | G9: 9.7277701e+11 | H9: =(D9/G9)-(E9/F9) -> -0.059692981
A10: 9 | B10: ASMI | C10: 2020 | D10: -86844513059 | E10: =D9 -> 10700535196 | F10: =G9 -> 9.7277701e+11 | G10: 9.833396e+11 | H10: =(D10/G10)-(E10/F10) -> -0.099315879
A11: 10 | B11: ASMI | C11: 2021 | D11: 19429664571 | E11: =D10 -> -86844513059 | F11: =G10 -> 9.833396e+11 | G11: 986040658507 | H11: =(D11/G11)-(E11/F11) -> 0.10802062
A12: 11 | B12: BBNI | C12: 2017 | D12: 15617639000000 | G12: 656180982000000 | H12: =(D12/G12)-(E12/F12) -> #DIV/0!
A13: 12 | B13: BBNI | C13: 2018 | D13: 14236252000000 | E13: =D12 -> 15617639000000 | F13: =G12 -> 656180982000000 | G13: 758951047500000 | H13: =(D13/G13)-(E13/F13) -> -0.0050430101
A14: 13 | B14: BBNI | C14: 2019 | D14: 18383939000000 | E14: =D13 -> 14236252000000 | F14: =G13 -> 758951047500000 | G14: 827088609500000 | H14: =(D14/G14)-(E14/F14) -> 0.0034694907
A15: 14 | B15: BBNI | C15: 2020 | D15: 4192722000000 | E15: =D14 -> 18383939000000 | F15: =G14 -> 827088609500000 | G15: 868471316500000 | H15: =(D15/G15)-(E15/F15) -> -0.017399587
A16: 15 | B16: BBNI | C16: 2021 | D16: 11722436000000 | E16: =D15 -> 4192722000000 | F16: =G15 -> 868471316500000 | G16: 928087558500000 | H16: =(D16/G16)-(E16/F16) -> 0.0078030401
A17: 16 | B17: BBTN | C17: 2017 | D17: 3056679000000 | G17: 237766873000000 | H17: =(D17/G17)-(E17/F17) -> #DIV/0!
A18: 17 | B18: BBTN | C18: 2018 | D18: 2782507000000 | E18: =D17 -> 3056679000000 | F18: =G17 -> 237766873000000 | G18: 283900730500000 | H18: =(D18/G18)-(E18/F18) -> -0.0030547959
A19: 18 | B19: BBTN | C19: 2019 | D19: 557332000000 | E19: =D18 -> 2782507000000 | F19: =G18 -> 283900730500000 | G19: 309106511000000 | H19: =(D19/G19)-(E19/F19) -> -0.0079979438
A20: 19 | B20: BBTN | C20: 2020 | D20: 2352711000000 | E20: =D19 -> 557332000000 | F20: =G19 -> 309106511000000 | G20: 336492617000000 | H20: =(D20/G20)-(E20/F20) -> 0.0051888232
A21: 20 | B21: BBTN | C21: 2021 | D21: 1418802000000 | E21: =D20 -> 2352711000000 | F21: =G20 -> 336492617000000 | G21: 366538358500000 | H21: =(D21/G21)-(E21/F21) -> -0.0031210506
A22: 21 | B22: BCAP | C22: 2017 | D22: -779107000000 | G22: 21049641000000 | H22: =(D22/G22)-(E22/F22) -> #DIV/0!
A23: 22 | B23: BCAP | C23: 2018 | D23: 103545000000 | E23: =D22 -> -779107000000 | F23: =G22 -> 21049641000000 | G23: 19322993500000 | H23: =(D23/G23)-(E23/F23) -> 0.042371482
A24: 23 | B24: BCAP | C24: 2019 | D24: 93737000000 | E24: =D23 -> 103545000000 | F24: =G23 -> 19322993500000 | G24: 18573864500000 | H24: =(D24/G24)-(E24/F24) -> -0.0003119268
A25: 24 | B25: BCAP | C25: 2020 | D25: 63228000000 | E25: =D24 -> 93737000000 | F25: =G24 -> 18573864500000 | G25: 18743275500000 | H25: =(D25/G25)-(E25/F25) -> -0.0016733451
A26: 25 | B26: BCAP | C26: 2021 | D26: 143486000000 | E26: =D25 -> 63228000000 | F26: =G25 -> 18743275500000 | G26: 20377757000000 | H26: =(D26/G26)-(E26/F26) -> 0.0036679351
A27: 26 | B27: BDMN | C27: 2017 | D27: 3708950000000 | G27: 176346806500000 | H27: =(D27/G27)-(E27/F27) -> #DIV/0!
A28: 27 | B28: BDMN | C28: 2018 | D28: 4126533000000 | E28: =D27 -> 3708950000000 | F28: =G27 -> 176346806500000 | G28: 182509640500000 | H28: =(D28/G28)-(E28/F28) -> 0.0015778095
A29: 28 | B29: BDMN | C29: 2019 | D29: 4330487000000 | E29: =D28 -> 4126533000000 | F29: =G28 -> 182509640500000 | G29: 190148079500000 | H29: =(D29/G29)-(E29/F29) -> 0.00016434198
A30: 29 | B30: BDMN | C30: 2020 | D30: 1382263000000 | E30: =D29 -> 4330487000000 | F30: =G29 -> 190148079500000 | G30: 197212019000000 | H30: =(D30/G30)-(E30/F30) -> -0.015765267
A31: 30 | B31: BDMN | C31: 2021 | D31: =1892628000000 -> 1892628000000 | E31: =D30 -> 1382263000000 | F31: =G30 -> 197212019000000 | G31: 196564883000000 | H31: =(D31/G31)-(E31/F31) -> 0.0026194953
A32: 31 | B32: BFIN | C32: 2017 | D32: 1158370000000 | G32: 14479764500000 | H32: =(D32/G32)-(E32/F32) -> #DIV/0!
A33: 32 | B33: BFIN | C33: 2018 | D33: 1538957000000 | E33: =D32 -> 1158370000000 | F33: =G32 -> 14479764500000 | G33: 17800289000000 | H33: =(D33/G33)-(E33/F33) -> 0.0064576254
A34: 33 | B34: BFIN | C34: 2019 | D34: 609633000000 | E34: =D33 -> 1538957000000 | F34: =G33 -> 17800289000000 | G34: 19103469000000 | H34: =(D34/G34)-(E34/F34) -> -0.054544693
A35: 34 | B35: BFIN | C35: 2020 | D35: 827932000000 | E35: =D34 -> 609633000000 | F35: =G34 -> 19103469000000 | G35: 17145082000000 | H35: =(D35/G35)-(E35/F35) -> 0.016377604
A36: 35 | B36: BFIN | C36: 2021 | D36: 1197691000000 | E36: =D35 -> 827932000000 | F36: =G35 -> 17145082000000 | G36: 15418135000000 | H36: =(D36/G36)-(E36/F36) -> 0.0293909
A37: 36 | B37: BNGA | C37: 2017 | D37: 2966276000000 | G37: 253938591500000 | H37: =(D37/G37)-(E37/F37) -> #DIV/0!
A38: 37 | B38: BNGA | C38: 2018 | D38: 3202980000000 | E38: =D37 -> 2966276000000 | F38: =G37 -> 253938591500000 | G38: 266543476500000 | H38: =(D38/G38)-(E38/F38) -> 0.00033565023
A39: 38 | B39: BNGA | C39: 2019 | D39: 4387474000000 | E39: =D38 -> 3202980000000 | F39: =G38 -> 266543476500000 | G39: 270624362500000 | H39: =(D39/G39)-(E39/F39) -> 0.004195687
A40: 39 | B40: BNGA | C40: 2020 | D40: 3289807000000 | E40: =D39 -> 4387474000000 | F40: =G39 -> 270624362500000 | G40: 277705416000000 | H40: =(D40/G40)-(E40/F40) -> -0.004366022
...

Sheet Financial Performance
A1: No | B1: Kode Emiten | C1: Tahun | D1: Ch Receivable | E1: Ch in cash sales | F1: Ch in earning | G1: Financial Performance
A2: 1 | B2: ASTJ | C2: 2017 | D2: ='ch receivable'!G2 -> #DIV/0! | E2: ='ch in cash sales'!J2 -> 0 | F2: ='Ch In earning'!H2 -> #DIV/0! | G2: =D2+E2+F2 -> #DIV/0!
A3: 2 | B3: ASTJ | C3: 2018 | D3: ='ch receivable'!G3 -> 0.008658414 | E3: ='ch in cash sales'!J3 -> -0.10477379 | F3: ='Ch In earning'!H3 -> -0.05976363 | G3: =D3+E3+F3 -> -0.15587901
A4: 3 | B4: ASTJ | C4: 2019 | D4: ='ch receivable'!G4 -> -0.017193492 | E4: ='ch in cash sales'!J4 -> 0.010790615 | F4: ='Ch In earning'!H4 -> -0.015610283 | G4: =D4+E4+F4 -> -0.02201316
A5: 4 | B5: ASTJ | C5: 2020 | D5: ='ch receivable'!G5 -> 0.012917324 | E5: ='ch in cash sales'!J5 -> -0.47619244 | F5: ='Ch In earning'!H5 -> -0.0057821261 | G5: =D5+E5+F5 -> -0.46905724
A6: 5 | B6: ASTJ | C6: 2021 | D6: ='ch receivable'!G6 -> 0.058677032 | E6: ='ch in cash sales'!J6 -> -0.12467227 | F6: ='Ch In earning'!H6 -> 0.0011869743 | G6: =D6+E6+F6 -> -0.064808266
A7: 6 | B7: ASMI | C7: 2017 | D7: ='ch receivable'!G7 -> #DIV/0! | E7: ='ch in cash sales'!J7 -> 0 | F7: ='Ch In earning'!H7 -> #DIV/0! | G7: =D7+E7+F7 -> #DIV/0!
A8: 7 | B8: ASMI | C8: 2018 | D8: ='ch receivable'!G8 -> 0.044723841 | E8: ='ch in cash sales'!J8 -> -0.10338084 | F8: ='Ch In earning'!H8 -> -0.012146129 | G8: =D8+E8+F8 -> -0.070803131
A9: 8 | B9: ASMI | C9: 2019 | D9: ='ch receivable'!G9 -> -0.0048834762 | E9: ='ch in cash sales'!J9 -> 0.11139192 | F9: ='Ch In earning'!H9 -> -0.059692981 | G9: =D9+E9+F9 -> 0.04681546
A10: 9 | B10: ASMI | C10: 2020 | D10: ='ch receivable'!G10 -> 0.088460707 | E10: ='ch in cash sales'!J10 -> -0.47814394 | F10: ='Ch In earning'!H10 -> -0.099315879 | G10: =D10+E10+F10 -> -0.48899911
A11: 10 | B11: ASMI | C11: 2021 | D11: ='ch receivable'!G11 -> -0.060512599 | E11: ='ch in cash sales'!J11 -> 1.6495227 | F11: ='Ch In earning'!H11 -> 0.10802062 | G11: =D11+E11+F11 -> 1.6970307
A12: 11 | B12: BBNI | C12: 2017 | D12: ='ch receivable'!G12 -> #DIV/0! | E12: ='ch in cash sales'!J12 -> 0 | F12: ='Ch In earning'!H12 -> #DIV/0! | G12: =D12+E12+F12 -> #DIV/0!
A13: 12 | B13: BBNI | C13: 2018 | D13: ='ch receivable'!G13 -> 0.095462149 | E13: ='ch in cash sales'!J13 -> -0.040578506 | F13: ='Ch In earning'!H13 -> -0.0050430101 | G13: =D13+E13+F13 -> 0.049840633
... A67: 66 | B67: HDFA | C67: 2017 | D67: ='ch receivable'!G67 -> #DIV/0! | E67: ='ch in cash sales'!J67 -> 0 | F67: ='Ch In earning'!H67 -> #DIV/0! | G67: =D67+E67+F67 -> #DIV/0!
A68: 67 | B68: HDFA | C68: 2018 | D68: =-'ch receivable'!G68 -> 0.66091734 | E68: =-'ch in cash sales'!J68 -> 0.038234056 | F68: =-'Ch In earning'!H68 -> 0.09880776 | G68: =D68+E68+F68 -> 0.79795916
A69: 68 | B69: HDFA | C69: 2019 | D69: =-'ch receivable'!G69 -> 0.61578342 | E69: ='ch in cash sales'!J69 -> 1.4300825 | F69: ='Ch In earning'!H69 -> -0.019091268 | G69: =D69+E69+F69 -> 2.0267747
A70: 69 | B70: HDFA | C70: 2020 | D70: =-'ch receivable'!G70 -> 0.22077424 | E70: =-'ch in cash sales'!J70 -> 0.97079334 | F70: ='Ch In earning'!H70 -> 0.028831051 | G70: =D70+E70+F70 -> 1.2203986
A71: 70 | B71: HDFA | C71: 2021 | D71: ='ch receivable'!G71 -> 0.67156344 | E71: =-'ch in cash sales'!J71 -> 0.3217801 | F71: ='Ch In earning'!H71 -> 0.13488696 | G71: =D71+E71+F71 -> 1.1282305
A72: 71 | B72: MAYA | C72: 2017 | D72: ='ch receivable'!G72 -> #DIV/0! | E72: ='ch in cash sales'!J72 -> 0 | F72: ='Ch In earning'!H72 -> #DIV/0! | G72: =D72+E72+F72 -> #DIV/0!
A73: 72 | B73: MAYA | C73: 2018 | D73: ='ch receivable'!G73 -> 0.10188344 | E73: ='ch in cash sales'!J73 -> -0.0022704792 | F73: ='Ch In earning'!H73 -> -0.0037681485 | G73: =D73+E73+F73 -> 0.095844816
A74: 73 | B74: MAYA | C74: 2019 | D74: ='ch receivable'!G74 -> 0.060768799 | E74: ='ch in cash sales'!J74 -> -0.094533668 | F74: ='Ch In earning'!H74 -> -0.00023958892 | G74: =D74+E74+F74 -> -0.034004458
A75: 74 | B75: MAYA | C75: 2020 | D75: =-'ch receivable'!G75 -> 0.16310158 | E75: =-'ch in cash sales'!J75 -> 0.53222034 | F75: ='Ch In earning'!H75 -> -0.0037467954 | G75: =D75+E75+F75 -> 0.69157512
A76: 75 | B76: MAYA | C76: 2021 | D76: ='ch receivable'!G76 -> 0.14796434 | E76: ='ch in cash sales'!J76 -> -0.35563177 | F76: ='Ch In earning'!H76 -> -0.0016807492 | G76: =D76+E76+F76 -> -0.20934818
A77: 76 | B77: PADI | C77: 2017 | D77: ='ch receivable'!G77 -> #DIV/0! | E77: ='ch in cash sales'!J77 -> 0 | F77: ='Ch In earning'!H77 -> #DIV/0! | G77: =D77+E77+F77 -> #DIV/0!
A78: 77 | B78: PADI | C78: 2018 | D78: =-'ch receivable'!G78 -> 0.031540805 | E78: =-'ch in cash sales'!J78 -> 1.55343 | F78: ='Ch In earning'!H78 -> -0.0067235307 | G78: =D78+E78+F78 -> 1.5782472
A79: 78 | B79: PADI | C79: 2019 | D79: ='ch receivable'!G79 -> -0.017745597 | E79: ='ch in cash sales'!J79 -> 1.8956843 | F79: ='Ch In earning'!H79 -> -0.36802953 | G79: =D79+E79+F79 -> 1.5099092
A80: 79 | B80: PADI | C80: 2020 | D80: ='ch receivable'!G80 -> 0.024059387 | E80: =-'ch in cash sales'!J80 -> 0.86665061 | F80: ='Ch In earning'!H80 -> 0.060645482 | G80: =D80+E80+F80 -> 0.95135548
A81: 80 | B81: PADI | C81: 2021 | D81: =-'ch receivable'!G81 -> 0.04402103 | E81: ='ch in cash sales'!J81 -> 0.98461743 | F81: ='Ch In earning'!H81 -> 0.057520258 | G81: =D81+E81+F81 -> 1.0861587
A82: 81 | B82: PNLF | C82: 2017 | D82: ='ch receivable'!G82 -> #DIV/0! | E82: ='ch in cash sales'!J82 -> 0 | F82: ='Ch In earning'!H82 -> #DIV/0! | G82: =D82+E82+F82 -> #DIV/0!
A83: 82 | B83: PNLF | C83: 2018 | D83: ='ch receivable'!G83 -> 0.0014425103 | E83: ='ch in cash sales'!J83 -> -0.38645848 | F83: ='Ch In earning'!H83 -> 0.0060938952 | G83: =D83+E83+F83 -> -0.37892207
A84: 83 | B84: PNLF | C84: 2019 | D84: ='ch receivable'!G84 -> 0.0016854192 | E84: ='ch in cash sales'!J84 -> -0.19604726 | F84: ='Ch In earning'!H84 -> 0.0065947279 | G84: =D84+E84+F84 -> -0.18776711
A85: 84 | B85: PNLF | C85: 2020 | D85: ='ch receivable'!G85 -> 0.0031164281 | E85: ='ch in cash sales'!J85 -> -0.82090918 | F85: ='Ch In earning'!H85 -> 0.016245391 | G85: =D85+E85+F85 -> -0.80154736
A86: 85 | B86: PNLF | C86: 2021 | D86: ='ch receivable'!G86 -> 0.00078878461 | E86: ='ch in cash sales'!J86 -> -0.11891685 | F86: ='Ch In earning'!H86 -> -0.061449537 | G86: =D86+E86+F86 -> -0.1795776
A87: 86 | B87: SDRA | C87: 2017 | D87: ='ch receivable'!G87 -> #DIV/0! | E87: ='ch in cash sales'!J87 -> 0 | F87: ='Ch In earning'!H87 -> #DIV/0! | G87: =D87+E87+F87 -> #DIV/0!
A88: 87 | B88: SDRA | C88: 2018 | D88: ='ch receivable'!G88 -> 0.13773132 | E88: ='ch in cash sales'!J88 -> -0.028414468 | F88: ='Ch In earning'!H88 -> 0.0017519535 | G88: =D88+E88+F88 -> 0.1110688
A89: 88 | B89: SDRA | C89: 2019 | D89: ='ch receivable'!G89 -> 0.1340184 | E89: ='ch in cash sales'!J89 -> -0.2357899 | F89: ='Ch In earning'!H89 -> -0.0045828277 | G89: =D89+E89+F89 -> -0.10635434
A90: 89 | B90: SDRA | C90: 2020 | D90: ='ch receivable'!G90 -> 0.084686511 | E90: ='ch in cash sales'!J90 -> -0.066058548 | F90: ='Ch In earning'!H90 -> -8.591549e-05 | G90: =D90+E90+F90 -> 0.018542048
A91: 90 | B91: SDRA | C91: 2021 | D91: ='ch receivable'!G91 -> 0.085905298 | E91: ='ch in cash sales'!J91 -> 0.032285607 | F91: ='Ch In earning'!H91 -> 0.00087534888 | G91: =D91+E91+F91 -> 0.11906625
A92: 91 | B92: SMMA | C92: 2017 | D92: ='ch receivable'!G92 -> #DIV/0! | E92: ='ch in cash sales'!J92 -> 0 | F92: ='Ch In earning'!H92 -> #DIV/0! | G92: =D92+E92+F92 -> #DIV/0!
A93: 92 | B93: SMMA | C93: 2018 | D93: ='ch receivable'!G93 -> 0.029218619 | E93: ='ch in cash sales'!J93 -> 0.024221977 | F93: ='Ch In earning'!H93 -> -0.010975313 | G93: =D93+E93+F93 -> 0.042465284
...

Sheet WC
A1: No | B1: Kode Emiten | C1: Tahun | D1: Current Assets | E1: Current Liabilities | F1: WC | G1: ∆WC
A2: 1 | B2: ASTJ | C2: 2017 | D2: =14519676151+713988211+'ch receivable'!D2+36882660220+30928753278 -> 188346950854 | E2: =234663726530-6310038845-15163595819 -> 213190091866 | F2: =D2-E2 -> -24843141012
A3: 2 | B3: ASTJ | C3: 2018 | D3: =11675712902+'ch receivable'!D3+713988216+64633898000+32186974591 -> 218515004183 | E3: =258813437264-5755573881-11221131258 -> 241836732125 | F3: =D3-E3 -> -23321727942 | G3: =F3-F2 -> 1521413070
A4: 3 | B4: ASTJ | C4: 2019 | D4: =9180911925+'ch receivable'!D4+68040900929+28371905434 -> 206936619136 | E4: =238307219450-1559666255-5816748324 -> 230930804871 | F4: =D4-E4 -> -23994185735 | G4: =F4-F3 -> -672457793
A5: 4 | B5: ASTJ | C5: 2020 | D5: =10218012106+'ch receivable'!D5+25044323082+14134896380 -> 155993828988 | E5: =156229284960-8520962475-10964575454 -> 136743747031 | F5: =D5-E5 -> 19250081957 | G5: =F5-F4 -> 43244267692
A6: 5 | B6: ASTJ | C6: 2021 | D6: =8301695852+'ch receivable'!D6+29453865309+65587930418 -> 236157460614 | E6: =219398368810-3324384530-24080932611 -> 191993051669 | F6: =D6-E6 -> 44164408945 | G6: =F6-F5 -> 24914326988
A7: 6 | B7: ASMI | C7: 2017 | D7: =3063169002+'ch receivable'!D7+123016373814 -> 265738628652 | E7: =403521972950-36619253244-14642983000-233483356743-18898350616 -> 99878029347 | F7: =D7-E7 -> 165860599305
A8: 7 | B8: ASMI | C8: 2018 | D8: =5853410707+'ch receivable'!D8+133703082559 -> 320101149649 | E8: =1113802274+89246619825+21790129723+545482187+12089534682 -> 124785568691 | F8: =D8-E8 -> 195315580958 | G8: =F8-F7 -> 29454981653
A9: 8 | B9: ASMI | C9: 2019 | D9: =10327839284+'ch receivable'!D9+130941453733 -> 317063416058 | E9: =1534991608+71566715136+15627966323+617272865+5147113476 -> 94494059408 | F9: =D9-E9 -> 222569356650 | G9: =F9-F8 -> 27253775692
A10: 9 | B10: ASMI | C10: 2020 | D10: =27753266725+'ch receivable'!D10+237751180761 -> 528285486877 | E10: =460283470+36757191276+22406237281+391760750+1230443792 -> 61245916569 | F10: =D10-E10 -> 467039570308 | G10: =F10-F9 -> 244470213658
A11: 10 | B11: ASMI | C11: 2021 | D11: =27286512817+'ch receivable'!D11+188451309212 -> 418850978640 | E11: =3237593569+3491647273+31148406534+633605432+4987600229 -> 43498853037 | F11: =D11-E11 -> 375352125603 | G11: =F11-F10 -> -91687444705
A12: 11 | B12: BBNI | C12: 2017 | D12: =11577664+32700717000000+21335150000000+28592738000000+'ch receivable'!D12 -> 536647607577664 | E12: =4867547000000+492747948000000+11734207000000+971479000000+80425000000+4093855000000 -> 514495461000000 | F12: =D12-E12 -> 22152146577664
A13: 12 | B13: BBNI | C13: 2018 | D13: =14043846000000+35591243000000+13133828000000+39324445000000+'ch receivable'!D13 -> 628563451000000 | E13: =671237546000000-99953000000-52024506000000-2987464-14608465000000-177519000000-4416613000000-21524329000000-322028000000 -> 578064130012536 | F13: =D13-E13 -> 50499320987464 | G13: =F13-F12 -> 28347174409800
A14: 13 | B14: BBNI | C14: 2019 | D14: =15361703000000+37104091000000+14962793000000+47776809000000+'ch receivable'!D14 -> 683514765000000 | E14: =688489442000000-99965000000-57235500000000-2985052000000-14900956000000-185019000000-5341440000000-203054000000-2183403000000 -> 605355053000000 | F14: =D14-E14 -> 78159712000000 | G14: =F14-F13 -> 27660391012536
A15: 14 | B15: BBNI | C15: 2020 | D15: =17324047000000+35065701000000+16107788000000+61329259000000+'ch receivable'!D14 -> 698136164000000 | E15: =746235663000000-99979000000-44114314000000-2985011000000-18280485000000-1421914000000-5500360000000-2590268000000-414280000000 -> 670829052000000 | F15: =D15-E15 -> 27307112000000 | G15: =F15-F14 -> -50852600000000
A16: 15 | B16: BBNI | C16: 2021 | D16: =13683598000000+48682431000000+19569891000000+92290210000000+'ch receivable'!D16 -> 735846646000000 | E16: =838317715000000-15764682000000-32457936000000-2986530000000-20542001000000-2276397000000-5588069000000-1828652000000-109948000000 -> 756763500000000 | F16: =D16-E16 -> -20916854000000 | G16: =F16-F15 -> -48223966000000
A17: 16 | B17: BBTN | C17: 2017 | D17: =1027554000000+12554585000000+556301000000+24697503000000+'ch receivable'!D17 -> 235478618000000 | E17: =223937463000000-2999319000000-5612462000000-7991053000000-20480459000000-8081000000-1385000000000-85481932000000 -> 99979157000000 | F17: =D17-E17 -> 135499461000000
A18: 17 | B18: BBTN | C18: 2018 | D18: =1243615000000+15417862000000+1587051000000+26464760000000+'ch receivable'!D18 -> 279700978000000 | E18: =263784017000000-2999519000000-6217814000000-15499493000000-20644760000000-528148000000-935000000000-115462283000000 -> 101497000000000 | F18: =D18-E18 -> 178203978000000 | G18: =F18-F17 -> 42704517000000
A19: 18 | B19: BBTN | C19: 2019 | D19: =1369167000000+1551239000000+747869000000+11097193000000+'ch receivable'!D19 -> 264961513000000 | E19: =269451682000000-5999669000000-5736637000000-19783552000000-22465657000000-487052000000-935000000000-113929798000000 -> 100114317000000 | F19: =D19-E19 -> 164847196000000 | G19: =F19-F18 -> -13356782000000
A20: 19 | B20: BBTN | C20: 2020 | D20: =1429426000000+11107672000000+3215321000000+19830433000000+'ch receivable'!D20 -> 282901116000000 | E20: =321376142000000-10194432000000-6666875000000-6489000000-15810466000000-23807138000000-22787000000-196071000000-147858608000000 -> 116813276000000 | F20: =D20-E20 -> 166087840000000 | G20: =F20-F19 -> 1240644000000
A21: 20 | B21: BBTN | C21: 2021 | D21: =1539577000000+10692484000000+1095100000000+27901048000000+'ch receivable'!D21 -> 302112274000000 | E21: =327693592000000-8759744000000-6618300000000-3644000000-12371708000000-22062291000000-17741000000-454140000000-146520589000000 -> 130885435000000 | F21: =D21-E21 -> 171226839000000 | G21: =F21-F20 -> 5138999000000
A22: 21 | B22: BCAP | C22: 2017 | D22: =1780674000000+34993000000+424687000000-10577000000+'ch receivable'!D22 -> 6553454000000 | E22: =533534000000+8443515000000+197257000000+14726000000+172534000000+27056000000 -> 9388622000000 | F22: =D22-E22 -> -2835168000000
A23: 22 | B23: BCAP | C23: 2018 | D23: =1927704000000+38316000000+309360000000-16490000000+'ch receivable'!D23 -> 5246022000000 | E23: =823273000000+7604794000000+740092000000+37937000000+113873000000+22277000000 -> 9342246000000 | F23: =D23-E23 -> -4096224000000 | G23: =(F23-F22) -> -1261056000000
A24: 23 | B24: BCAP | C24: 2019 | D24: =1177395000000+39229000000+342371000000-25108000000+'ch receivable'!D24 -> 4131645000000 | E24: =409096000000+7895637000000+393715000000+48486000000+201472000000+313175000000+32272000000 -> 9293853000000 | F24: =D24-E24 -> -5162208000000 | G24: =(F24-F23) -> -1065984000000
A25: 24 | B25: BCAP | C25: 2020 | D25: =1758171000000+43458000000+310482000000-34031000000+'ch receivable'!D25 -> 4672634000000 | E25: =753682000000+8315127000000+490103000000+173797000000+421663000000+498855000000+25398000000 -> 10678625000000 | F25: =D25-E25 -> -6005991000000 | G25: =(F25-F24) -> -843783000000
A26: 25 | B26: BCAP | C26: 2021 | D26: =2827492000000+28473000000+304095000000-34781000000+'ch receivable'!D26 -> 5431154000000 | E26: =11123446000000+130675000000+69299000000+385506000000+347083000000+29696000000 -> 12085705000000 | F26: =D26-E26 -> -6654551000000 | G26: =(F26-F25) -> -648560000000
A27: 26 | B27: BDMN | C27: 2017 | D27: =2546414000000+7555916000000+221082000000+1810940000000+5198885000000+'ch receivable'!D27+697170000000 -> 140368274000000 | E27: =129971000000+101766847000000+4634513000000+116526000000 -> 106647857000000 | F27: =D27-E27 -> 33720417000000
A28: 27 | B28: BDMN | C28: 2018 | D28: =2823776000000+6459517000000+112282000000+1274889000000+8576062000000+'ch receivable'!D28 -> 143923553000000 | E28: =118980000000+107576816000000+3152422000000+87011000000 -> 110935229000000 | F28: =D28-E28 -> 32988324000000 | G28: =F28-F27 -> -732093000000
A29: 28 | B29: BDMN | C29: 2019 | D29: =2950563000000+5403446000000+15945000000+2599729000000+189886000000+5400836000000+'ch receivable'!D29 -> 154362647000000 | E29: =590957000000+109200953000000+266031000000+4215474000000+473076000000 -> 114746491000000 | F29: =D29-E29 -> 39616156000000 | G29: =F29-F28 -> 6627832000000
A30: 29 | B30: BDMN | C30: 2020 | D30: =2838127000000+2185998000000+5208000000+4411865000000+7303551000000+'ch receivable'!D30 -> 145488655000000 | E30: =298081000000+123435123000000+78494000000+2399231000000+300857000000 -> 126511786000000 | F30: =D30-E30 -> 18976869000000 | G30: =F30-F29 -> -20639287000000
A31: 30 | B31: BDMN | C31: 2021 | D31: =2789555000000+3060014000000+176550000000+2801084000000+9888484000000+'ch receivable'!D31 -> 141166331000000 | E31: =962547000000+120106770000000+65813000000+2218774000000+212184000000 -> 123566088000000 | F31: =D31-E31 -> 17600243000000 | G31: =F31-F30 -> -1376626000000
A32: 31 | B32: BFIN | C32: 2017 | D32: =225203000000+'ch receivable'!D32 -> 15814055000000 | E32: =6819052000000+140151000000+293527000000+199716000000 -> 7452446000000 | F32: =D32-E32 -> 8361609000000
A33: 32 | B33: BFIN | C33: 2018 | D33: =755247000000+'ch receivable'!D33 -> 18234081000000 | E33: =6899860000000+67063000000+287878000000+202498000000 -> 7457299000000 | F33: =D33-E33 -> 10776782000000 | G33: =F33-F32 -> 2415173000000
A34: 33 | B34: BFIN | C34: 2019 | D34: =660032000000+'ch receivable'!D34 -> 18211551000000 | E34: =7730021000000+73271000000+796709000000+258337000000 -> 8858338000000 | F34: =D34-E34 -> 9353213000000 | G34: =F34-F33 -> -1423569000000
A35: 34 | B35: BFIN | C35: 2020 | D35: =1414691000000+'ch receivable'!D35 -> 14248625000000 | E35: =4794844000000+101719000000+194038000000+154211000000 -> 5244812000000 | F35: =D35-E35 -> 9003813000000 | G35: =F35-F34 -> -349400000000
A36: 35 | B36: BFIN | C36: 2021 | D36: =969182000000+'ch receivable'!D36 -> 14733402000000 | E36: =4789422000000+120131000000+338442000000+115457000000 -> 5363452000000 | F36: =D36-E36 -> 9369950000000 | G36: =F36-F35 -> 366137000000
A37: 36 | B37: BNGA | C37: 2017 | D37: =3889241000000+11522696000000+3529272000000+13314199000000+'ch receivable'!D37 -> 221847408000000 | E37: =1946166000000+49281023000000+50214272000000+6884335000000+445502000000+2986666000000+1289985000000 -> 113047949000000 | F37: =D37-E37 -> 108799459000000
A38: 37 | B38: BNGA | C38: 2018 | D38: =4290614000000+10435254000000+3024143000000+9227275000000+'ch receivable'!D38 -> 214889787000000 | E38: =2240191000000+45857151000000+54495883000000+2928693000000+461141000000+3594738000000+930196000000 -> 110507993000000 | F38: =D38-E38 -> 104381794000000 | G38: =F38-F37 -> -4417665000000
A39: 38 | B39: BNGA | C39: 2019 | D39: =5691444000000+11395695000000+2138408000000+12104730000000+'ch receivable'!D39 -> 224000336000000 | E39: =1781962000000+48943913000000+59316069000000+1364586000000+498541000000+4038684000000+1131727000000 -> 117075482000000 | F39: =D39-E39 -> 106924854000000 | G39: =F39-F38 -> 2543060000000
A40: 39 | B40: BNGA | C40: 2020 | D40: =4777284000000+6221892000000+3697487000000+13334150000000+'ch receivable'!D40 -> 194242397000000 | E40: =3636684000000+55862547000000+67861369000000+2901556000000+301192000000+5151393000000+1098334000000 -> 136813075000000 | F40: =D40-E40 -> 57429322000000 | G40: =F40-F39 -> -49495532000000
...

Sheet NCO
A1: No | B1: Kode Emiten | C1: Tahun | D1: Total Asset | E1: Current Assets | F1: Total Investment | G1: Advance | H1: Investment and advance | I1: Total Liabilities | J1: Current Liabilities | K1: Long Term Debt | L1: aset | M1: Liability | N1: NCO | O1: ∆NCO
A2: 1 | B2: ASTJ | C2: 2017 | D2: 446108163202 | E2: 188346950854 | F2: =103908836000+3234710450+61848752000+1620816770 -> 170613115220 | G2: 3610490079 | H2: =F2+G2 -> 174223605299 | I2: 234660000000 | J2: =234663726530-6310038845-15163595819 -> 213190091866 | K2: 15163595819 | L2: =(D2-E2-H2) -> 83537607049 | M2: =I2-J2-K2 -> 6306312315 | N2: =L2-M2 -> 77231294734
A3: 2 | B3: ASTJ | C3: 2018 | D3: 478439333039 | E3: 218515004183 | F3: =84331935000+3550789980+71177900000+1895208583 -> 160955833563 | G3: 3356888543 | H3: =F3+G3 -> 164312722106 | I3: 258810000000 | J3: =258813437264-5755573881-11221131258 -> 241836732125 | K3: 11221131258 | L3: =(D3-E3-H3) -> 95611606750 | M3: =I3-J3-K3 -> 5752136617 | N3: =L3-M3 -> 89859470133 | O3: =N3-N2 -> 12628175399
A4: 3 | B4: ASTJ | C4: 2019 | D4: 447670324778 | E4: 206936619136 | F4: =70658560550+3013810200+2091379533+1000000000 -> 76763750283 | G4: 8090524237 | H4: =F4+G4 -> 84854274520 | I4: 238310000000 | J4: =238307219450-1559666255-5816748324 -> 230930804871 | K4: 5816748324 | L4: =(D4-E4-H4) -> 155879431122 | M4: =I4-J4-K4 -> 1562446805 | N4: =L4-M4 -> 154316984317 | O4: =N4-N3 -> 64457514184
A5: 4 | B5: ASTJ | C5: 2020 | D5: 365763908254 | E5: 155993828988 | F5: =53165125250+3389308660+38807515000+2311324759+1000000000 -> 98673273669 | G5: 5338247012 | H5: =F5+G5 -> 104011520681 | I5: 156230000000 | J5: =156229284960-8520962475-10964575454 -> 136743747031 | K5: 10964575454 | L5: =(D5-E5-H5) -> 105758558585 | M5: =I5-J5-K5 -> 8521677515 | N5: =L5-M5 -> 97236881070 | O5: =N5-N4 -> -57080103247
A6: 5 | B6: ASTJ | C6: 2021 | D6: 527852244647 | E6: 236157460614 | F6: =122869225125+2252634930+56976096000+2184084778+1000000000 -> 185282040833 | G6: 8077944677 | H6: =F6+G6 -> 193359985510 | I6: 219400000000 | J6: =219398368810-3324384530-24080932611 -> 191993051669 | K6: 24080932611 | L6: =(D6-E6-H6) -> 98334798523 | M6: =I6-J6-K6 -> 3326015720 | N6: =L6-M6 -> 95008782803 | O6: =N6-N5 -> -2228098267
A7: 6 | B7: ASMI | C7: 2017 | D7: 858490283480 | E7: 265738628652 | F7: =203559267612+199781087636+120962510367+7313197000+1901731313 -> 533517793928 | G7: 2514688946 | H7: =F7+G7 -> 536032482874 | I7: 403521972590 | J7: =403521972950-36619253244-14642983000-233483356743-18898350616 -> 99878029347 | K7: 36619253244 | L7: =(D7-E7-H7) -> 56719171954 | M7: =I7-J7-K7 -> 267024689999 | N7: =L7-M7 -> -210305518045
A8: 7 | B8: ASMI | C8: 2018 | D8: 969866560976 | E8: 320101149649 | F8: =231082763503+229934584995+122306586000+7058080000+1901731313 -> 592283745811 | G8: 7717961287 | H8: =F8+G8 -> 600001707098 | I8: 450272263738 | J8: =1113802274+89246619825+21790129723+545482187+12089534682 -> 124785568691 | K8: 37067363957 | L8: =(D8-E8-H8) -> 49763704229 | M8: =I8-J8-K8 -> 288419331090 | N8: =L8-M8 -> -238655626861 | O8: =N8-N7 -> -28350108816
A9: 8 | B9: ASMI | C9: 2019 | D9: 975687462693 | E9: 317063416058 | F9: =216749320000+351654846593+18196797270+7268626000 -> 593869589863 | G9: 11190946006 | H9: =F9+G9 -> 605060535869 | I9: 445392630259 | J9: =1534991608+71566715136+15627966323+617272865+5147113476 -> 94494059408 | K9: 61784924599 | L9: =(D9-E9-H9) -> 53563510766 | M9: =I9-J9-K9 -> 289113646252 | N9: =L9-M9 -> -235550135486 | O9: =N9-N8 -> 3105491375
A10: 9 | B10: ASMI | C10: 2020 | D10: 990991744064 | E10: 528285486877 | F10: =61000000000+299816222397+18196797270+5416648000 -> 384429667667 | G10: 12967320338 | H10: =F10+G10 -> 397396988005 | I10: 547541424689 | J10: =460283470+36757191276+22406237281+391760750+1230443792 -> 61245916569 | K10: 56237287760 | L10: =(D10-E10-H10) -> 65309269182 | M10: =I10-J10-K10 -> 430058220360 | N10: =L10-M10 -> -364748951178 | O10: =N10-N9 -> -129198815692
A11: 10 | B11: ASMI | C11: 2021 | D11: 981089572950 | E11: 418850978640 | F11: =79736000000+323916974817+10377006750+47111957330 -> 461141938897 | G11: 25737796822 | H11: =F11+G11 -> 486879735719 | I11: 518209589004 | J11: =3237593569+3491647273+31148406534+633605432+4987600229 -> 43498853037 | K11: 27945351289 | L11: =(D11-E11-H11) -> 75358858591 | M11: =I11-J11-K11 -> 446765384678 | N11: =L11-M11 -> -371406526087 | O11: =N11-N10 -> -6657574909
A12: 11 | B12: BBNI | C12: 2017 | D12: 709330084000000 | E12: 536647607577664 | F12: =36049899000000+679122000000+79849452000000+713423000000 -> 117291896000000 | G12: 2318516000000 | H12: =F12+G12 -> 119610412000000 | I12: 584086818000000 | J12: =4867547000000+492747948000000+11734207000000+971479000000+80425000000+4093855000000 -> 514495461000000 | K12: =2390066000000+2986279000000+44670741000000 -> 50047086000000 | L12: =(D12-E12-H12) -> 53072064422336 | M12: =I12-J12-K12 -> 19544271000000 | N12: =L12-M12 -> 33527793422336
A13: 12 | B13: BBNI | C13: 2018 | D13: 808572011000000 | E13: 628563451000000 | F13: =32044270000000+86791402000000+603923000000 -> 119439595000000 | G13: 2337403000000 | H13: =F13+G13 -> 121776998000000 | I13: 671237546000000 | J13: =671237546000000-99953000000-52024506000000-2987464-14608465000000-177519000000-4416613000000-21524329000000-322028000000 -> 578064130012536 | K13: =21524329000000+2987464000000+52024506000000+99953000000 -> 76636252000000 | L13: =(D13-E13-H13) -> 58231562000000 | M13: =I13-J13-K13 -> 16537163987464 | N13: =L13-M13 -> 41694398012536 | O13: =N13-N12 -> 8166604590200
A14: 13 | B14: BBNI | C14: 2019 | D14: 845605208000000 | E14: 683514765000000 | F14: =27161751000000+411442000000+81029020000000+523103000000 -> 109125316000000 | G14: 2609259000000 | H14: =F14+G14 -> 111734575000000 | I14: 688489442000000 | J14: =688489442000000-99965000000-57235500000000-2985052000000-14900956000000-185019000000-5341440000000-203054000000-2183403000000 -> 605355053000000 | K14: =2183403000000+2985052000000+57235500000000+99965000000 -> 62503920000000 | L14: =(D14-E14-H14) -> 50355868000000 | M14: =I14-J14-K14 -> 20630469000000 | N14: =L14-M14 -> 29725399000000 | O14: =N14-N13 -> -11968999012536
A15: 14 | B15: BBNI | C15: 2020 | D15: 891337425000000 | E15: 698136164000000 | F15: =29686597000000+8666091000000+90659318000000+813087000000 -> 129825093000000 | G15: 2807092000000 | H15: =F15+G15 -> 132632185000000 | I15: 746235663000000 | J15: =746235663000000-99979000000-44114314000000-2985011000000-18280485000000-1421914000000-5500360000000-2590268000000-414280000000 -> 670829052000000 | K15: =2590268000000+2985011000000+44114314000000+99975000000 -> 49789568000000 | L15: =(D15-E15-H15) -> 60569076000000 | M15: =I15-J15-K15 -> 25617043000000 | N15: =L15-M15 -> 34952033000000 | O15: =N15-N14 -> 5226634000000
A16: 15 | B16: BBNI | C16: 2021 | D16: 964837692000000 | E16: 735846646000000 | F16: =8688406000000+111428330000000+22010968000000+25802962000000+829763000000 -> 168760429000000 | G16: 3095927000000 | H16: =F16+G16 -> 171856356000000 | I16: 838317715000000 | J16: =838317715000000-15764682000000-32457936000000-2986530000000-20542001000000-2276397000000-5588069000000-1828652000000-109948000000 -> 756763500000000 | K16: =1828652000000+2986530000000+32457936000000+15764682000000 -> 53037800000000 | L16: =(D16-E16-H16) -> 57134690000000 | M16: =I16-J16-K16 -> 28516415000000 | N16: =L16-M16 -> 28618275000000 | O16: =N16-N15 -> -6333758000000
A17: 16 | B17: BBTN | C17: 2017 | D17: 261365267000000 | E17: 235478618000000 | F17: =7706031000000+8183973000000 -> 15890004000000 | G17: =769454000000+413079000000 -> 1182533000000 | H17: =F17+G17 -> 17072537000000 | I17: 223937463000000 | J17: =223937463000000-2999319000000-5612462000000-7991053000000-20480459000000-8081000000-1385000000000-85481932000000 -> 99979157000000 | K17: =85481932000000+7991053000000+2999319000000 -> 96472304000000 | L17: =(D17-E17-H17) -> 8814112000000 | M17: =I17-J17-K17 -> 27486002000000 | N17: =L17-M17 -> -18671890000000
A18: 17 | B18: BBTN | C18: 2018 | D18: 306436194000000 | E18: 279700978000000 | F18: =5848485000000+9393138000000 -> 15241623000000 | G18: =1270875000000+409138000000 -> 1680013000000 | H18: =F18+G18 -> 16921636000000 | I18: 263784017000000 | J18: =263784017000000-2999519000000-6217814000000-15499493000000-20644760000000-528148000000-935000000000-115462283000000 -> 101497000000000 | K18: =115462283000000+15499493000000+2999519000000 -> 133961295000000 | L18: =(D18-E18-H18) -> 9813580000000 | M18: =I18-J18-K18 -> 28325722000000 | N18: =L18-M18 -> -18512142000000 | O18: =N18-N17 -> 159748000000
A19: 18 | B19: BBTN | C19: 2019 | D19: 311776828000000 | E19: 264961513000000 | F19: =8084671000000+11053601000000+1875221000000 -> 21013493000000 | G19: =402428000000+803479000000 -> 1205907000000 | H19: =F19+G19 -> 22219400000000 | I19: 269451682000000 | J19: =269451682000000-5999669000000-5736637000000-19783552000000-22465657000000-487052000000-935000000000-113929798000000 -> 100114317000000 | K19: =113929768000000+22465657000000+5999669000000 -> 142395094000000 | L19: =(D19-E19-H19) -> 24595915000000 | M19: =I19-J19-K19 -> 26942271000000 | N19: =L19-M19 -> -2346356000000 | O19: =N19-N18 -> 16165786000000
A20: 19 | B20: BBTN | C20: 2020 | D20: 361208406000000 | E20: 282901116000000 | F20: =3203966000000+56287751000000+954955000000 -> 60446672000000 | G20: =402428000000+386848000000 -> 789276000000 | H20: =F20+G20 -> 61235948000000 | I20: 321376142000000 | J20: =321376142000000-10194432000000-6666875000000-6489000000-15810466000000-23807138000000-22787000000-196071000000-147858608000000 -> 116813276000000 | K20: =147858608000000+23807138000000+10194432000000 -> 181860178000000 | L20: =(D20-E20-H20) -> 17071342000000 | M20: =I20-J20-K20 -> 22702688000000 | N20: =L20-M20 -> -5631346000000 | O20: =N20-N19 -> -3284990000000
A21: 20 | B21: BBTN | C21: 2021 | D21: 371868311000000 | E21: 302112274000000 | F21: =2230905000000+46080298000000+1598325000000 -> 49909528000000 | G21: =402428000000+367925000000 -> 770353000000 | H21: =F21+G21 -> 50679881000000 | I21: 327693592000000 | J21: =327693592000000-8759744000000-6618300000000-3644000000-12371708000000-22062291000000-17741000000-454140000000-146520589000000 -> 130885435000000 | K21: =146520589000000+22062291000000+8759744000000 -> 177342624000000 | L21: =(D21-E21-H21) -> 19076156000000 | M21: =I21-J21-K21 -> 19465533000000 | N21: =L21-M21 -> -389377000000 | O21: =N21-N20 -> 5241969000000
A22: 21 | B22: BCAP | C22: 2017 | D22: 19883263000000 | E22: 6553454000000 | F22: =7012000000+269888000000+3998739000000 -> 4275639000000 | G22: =20083000000+40830000000 -> 60913000000 | H22: =F22+G22 -> 4336552000000 | I22: 14255743000000 | J22: =533534000000+8443515000000+197257000000+14726000000+172534000000+27056000000 -> 9388622000000 | K22: =288999000000+2002729000000+556018000000+105067000000+294208000000+47394000000 -> 3294415000000 | L22: =(D22-E22-H22) -> 8993257000000 | M22: =I22-J22-K22 -> 1572706000000 | N22: =L22-M22 -> 7420551000000
A23: 22 | B23: BCAP | C23: 2018 | D23: 18762724000000 | E23: 5246022000000 | F23: =254124000000+3951878000000 -> 4206002000000 | G23: =20689000000+37985000000 -> 58674000000 | H23: =F23+G23 -> 4264676000000 | I23: 13015396000000 | J23: =823273000000+7604794000000+740092000000+37937000000+113873000000+22277000000 -> 9342246000000 | K23: =149244000000+1442761000000+393305000000+12605000000+365566000000+56620000000 -> 2420101000000 | L23: =(D23-E23-H23) -> 9252026000000 | M23: =I23-J23-K23 -> 1253049000000 | N23: =L23-M23 -> 7998977000000 | O23: =N23-N22 -> 578426000000
